2018-08-26 22:23:42,444 ERROR: Exception on /main/user/lu2905363 [GET] [in /home/lu2905363/PycharmProjects/flask/venv/lib/python3.6/site-packages/flask/app.py:1761]
Traceback (most recent call last):
  File "/home/lu2905363/PycharmProjects/flask/venv/lib/python3.6/site-packages/flask/app.py", line 2292, in wsgi_app
    response = self.full_dispatch_request()
  File "/home/lu2905363/PycharmProjects/flask/venv/lib/python3.6/site-packages/flask/app.py", line 1815, in full_dispatch_request
    rv = self.handle_user_exception(e)
  File "/home/lu2905363/PycharmProjects/flask/venv/lib/python3.6/site-packages/flask/app.py", line 1718, in handle_user_exception
    reraise(exc_type, exc_value, tb)
  File "/home/lu2905363/PycharmProjects/flask/venv/lib/python3.6/site-packages/flask/_compat.py", line 35, in reraise
    raise value
  File "/home/lu2905363/PycharmProjects/flask/venv/lib/python3.6/site-packages/flask/app.py", line 1813, in full_dispatch_request
    rv = self.dispatch_request()
  File "/home/lu2905363/PycharmProjects/flask/venv/lib/python3.6/site-packages/flask/app.py", line 1799, in dispatch_request
    return self.view_functions[rule.endpoint](**req.view_args)
  File "/home/lu2905363/PycharmProjects/flask/venv/lib/python3.6/site-packages/flask_login/utils.py", line 261, in decorated_view
    return func(*args, **kwargs)
  File "/home/lu2905363/PycharmProjects/flask/app/main/routes.py", line 55, in user
    return render_template('user.html', user=user, posts=posts.items, next_url=next_url, prev_url=prev_url)
  File "/home/lu2905363/PycharmProjects/flask/venv/lib/python3.6/site-packages/flask/templating.py", line 135, in render_template
    context, ctx.app)
  File "/home/lu2905363/PycharmProjects/flask/venv/lib/python3.6/site-packages/flask/templating.py", line 117, in _render
    rv = template.render(context)
  File "/home/lu2905363/PycharmProjects/flask/venv/lib/python3.6/site-packages/jinja2/asyncsupport.py", line 76, in render
    return original_render(self, *args, **kwargs)
  File "/home/lu2905363/PycharmProjects/flask/venv/lib/python3.6/site-packages/jinja2/environment.py", line 1008, in render
    return self.environment.handle_exception(exc_info, True)
  File "/home/lu2905363/PycharmProjects/flask/venv/lib/python3.6/site-packages/jinja2/environment.py", line 780, in handle_exception
    reraise(exc_type, exc_value, tb)
  File "/home/lu2905363/PycharmProjects/flask/venv/lib/python3.6/site-packages/jinja2/_compat.py", line 37, in reraise
    raise value.with_traceback(tb)
  File "/home/lu2905363/PycharmProjects/flask/app/templates/user.html", line 1, in top-level template code
    {% extends "base.html" %}
  File "/home/lu2905363/PycharmProjects/flask/app/templates/base.html", line 1, in top-level template code
    {% extends 'bootstrap/base.html' %}
  File "/home/lu2905363/PycharmProjects/flask/venv/lib/python3.6/site-packages/flask_bootstrap/templates/bootstrap/base.html", line 1, in top-level template code
    {% block doc -%}
  File "/home/lu2905363/PycharmProjects/flask/venv/lib/python3.6/site-packages/flask_bootstrap/templates/bootstrap/base.html", line 4, in block "doc"
    {%- block html %}
  File "/home/lu2905363/PycharmProjects/flask/venv/lib/python3.6/site-packages/flask_bootstrap/templates/bootstrap/base.html", line 20, in block "html"
    {% block body -%}
  File "/home/lu2905363/PycharmProjects/flask/venv/lib/python3.6/site-packages/flask_bootstrap/templates/bootstrap/base.html", line 23, in block "body"
    {% block content -%}
  File "/home/lu2905363/PycharmProjects/flask/app/templates/base.html", line 55, in block "content"
    {% block app_content %}{% endblock %}
  File "/home/lu2905363/PycharmProjects/flask/app/templates/user.html", line 17, in block "app_content"
    <p><a href="{{ url_for('unfollow', username=user.username) }}">Unfollow</a></p>
  File "/home/lu2905363/PycharmProjects/flask/venv/lib/python3.6/site-packages/flask/helpers.py", line 356, in url_for
    return appctx.app.handle_url_build_error(error, endpoint, values)
  File "/home/lu2905363/PycharmProjects/flask/venv/lib/python3.6/site-packages/flask/app.py", line 2061, in handle_url_build_error
    reraise(exc_type, exc_value, tb)
  File "/home/lu2905363/PycharmProjects/flask/venv/lib/python3.6/site-packages/flask/_compat.py", line 35, in reraise
    raise value
  File "/home/lu2905363/PycharmProjects/flask/venv/lib/python3.6/site-packages/flask/helpers.py", line 345, in url_for
    force_external=external)
  File "/home/lu2905363/PycharmProjects/flask/venv/lib/python3.6/site-packages/werkzeug/routing.py", line 1776, in build
    raise BuildError(endpoint, values, method, self)
werkzeug.routing.BuildError: Could not build url for endpoint 'unfollow' with values ['username']. Did you mean 'main.unfollow' instead?
2018-08-26 22:26:03,890 INFO: Microblog startup [in /home/lu2905363/PycharmProjects/flask/app/__init__.py:67]
2018-08-27 09:09:28,528 INFO: Microblog startup [in /home/lu2905363/PycharmProjects/flask/app/__init__.py:67]
2018-08-27 09:14:40,010 INFO: Microblog startup [in /home/lu2905363/PycharmProjects/flask/app/__init__.py:67]
2018-08-27 09:15:53,494 INFO: Microblog startup [in /home/lu2905363/PycharmProjects/flask/app/__init__.py:67]
2018-08-27 09:20:53,768 INFO: Microblog startup [in /home/lu2905363/PycharmProjects/flask/app/__init__.py:67]
