2018-08-25 16:19:46,827 ERROR: Exception on /login [GET] [in /home/lu2905363/PycharmProjects/flask/venv/lib/python3.6/site-packages/flask/app.py:1761]
Traceback (most recent call last):
  File "/home/lu2905363/PycharmProjects/flask/venv/lib/python3.6/site-packages/flask/app.py", line 2292, in wsgi_app
    response = self.full_dispatch_request()
  File "/home/lu2905363/PycharmProjects/flask/venv/lib/python3.6/site-packages/flask/app.py", line 1815, in full_dispatch_request
    rv = self.handle_user_exception(e)
  File "/home/lu2905363/PycharmProjects/flask/venv/lib/python3.6/site-packages/flask/app.py", line 1718, in handle_user_exception
    reraise(exc_type, exc_value, tb)
  File "/home/lu2905363/PycharmProjects/flask/venv/lib/python3.6/site-packages/flask/_compat.py", line 35, in reraise
    raise value
  File "/home/lu2905363/PycharmProjects/flask/venv/lib/python3.6/site-packages/flask/app.py", line 1813, in full_dispatch_request
    rv = self.dispatch_request()
  File "/home/lu2905363/PycharmProjects/flask/venv/lib/python3.6/site-packages/flask/app.py", line 1799, in dispatch_request
    return self.view_functions[rule.endpoint](**req.view_args)
  File "/home/lu2905363/PycharmProjects/flask/app/routes.py", line 62, in login
    return render_template('login.html', title='Sign In', form=form)
  File "/home/lu2905363/PycharmProjects/flask/venv/lib/python3.6/site-packages/flask/templating.py", line 135, in render_template
    context, ctx.app)
  File "/home/lu2905363/PycharmProjects/flask/venv/lib/python3.6/site-packages/flask/templating.py", line 117, in _render
    rv = template.render(context)
  File "/home/lu2905363/PycharmProjects/flask/venv/lib/python3.6/site-packages/jinja2/asyncsupport.py", line 76, in render
    return original_render(self, *args, **kwargs)
  File "/home/lu2905363/PycharmProjects/flask/venv/lib/python3.6/site-packages/jinja2/environment.py", line 1008, in render
    return self.environment.handle_exception(exc_info, True)
  File "/home/lu2905363/PycharmProjects/flask/venv/lib/python3.6/site-packages/jinja2/environment.py", line 780, in handle_exception
    reraise(exc_type, exc_value, tb)
  File "/home/lu2905363/PycharmProjects/flask/venv/lib/python3.6/site-packages/jinja2/_compat.py", line 37, in reraise
    raise value.with_traceback(tb)
  File "/home/lu2905363/PycharmProjects/flask/app/templates/login.html", line 2, in top-level template code
    {% import 'bootstrap/wtf.html' as wtf %}
  File "/home/lu2905363/PycharmProjects/flask/app/templates/base.html", line 1, in top-level template code
    {% extends 'bootstrap/base.html' %}
  File "/home/lu2905363/PycharmProjects/flask/venv/lib/python3.6/site-packages/flask_bootstrap/templates/bootstrap/base.html", line 1, in top-level template code
    {% block doc -%}
  File "/home/lu2905363/PycharmProjects/flask/venv/lib/python3.6/site-packages/flask_bootstrap/templates/bootstrap/base.html", line 4, in block "doc"
    {%- block html %}
  File "/home/lu2905363/PycharmProjects/flask/venv/lib/python3.6/site-packages/flask_bootstrap/templates/bootstrap/base.html", line 20, in block "html"
    {% block body -%}
  File "/home/lu2905363/PycharmProjects/flask/venv/lib/python3.6/site-packages/flask_bootstrap/templates/bootstrap/base.html", line 23, in block "body"
    {% block content -%}
  File "/home/lu2905363/PycharmProjects/flask/app/templates/base.html", line 55, in block "content"
    {% block app_content %}{% endblock %}
  File "/home/lu2905363/PycharmProjects/flask/app/templates/login.html", line 15, in block "app_content"
    <a href="{{ url_for('reset_password_request') }}">Click to Reset It</a>
  File "/home/lu2905363/PycharmProjects/flask/venv/lib/python3.6/site-packages/flask/helpers.py", line 356, in url_for
    return appctx.app.handle_url_build_error(error, endpoint, values)
  File "/home/lu2905363/PycharmProjects/flask/venv/lib/python3.6/site-packages/flask/app.py", line 2061, in handle_url_build_error
    reraise(exc_type, exc_value, tb)
  File "/home/lu2905363/PycharmProjects/flask/venv/lib/python3.6/site-packages/flask/_compat.py", line 35, in reraise
    raise value
  File "/home/lu2905363/PycharmProjects/flask/venv/lib/python3.6/site-packages/flask/helpers.py", line 345, in url_for
    force_external=external)
  File "/home/lu2905363/PycharmProjects/flask/venv/lib/python3.6/site-packages/werkzeug/routing.py", line 1776, in build
    raise BuildError(endpoint, values, method, self)
werkzeug.routing.BuildError: Could not build url for endpoint 'reset_password_request'. Did you mean 'edit_profile' instead?
2018-08-25 17:57:23,847 INFO: Microblog startup [in /home/lu2905363/PycharmProjects/flask/app/__init__.py:48]
2018-08-25 17:58:02,067 INFO: Microblog startup [in /home/lu2905363/PycharmProjects/flask/app/__init__.py:48]
2018-08-25 17:58:13,051 ERROR: Exception on /reset_password_request [GET] [in /home/lu2905363/PycharmProjects/flask/venv/lib/python3.6/site-packages/flask/app.py:1761]
Traceback (most recent call last):
  File "/home/lu2905363/PycharmProjects/flask/venv/lib/python3.6/site-packages/flask/app.py", line 2292, in wsgi_app
    response = self.full_dispatch_request()
  File "/home/lu2905363/PycharmProjects/flask/venv/lib/python3.6/site-packages/flask/app.py", line 1815, in full_dispatch_request
    rv = self.handle_user_exception(e)
  File "/home/lu2905363/PycharmProjects/flask/venv/lib/python3.6/site-packages/flask/app.py", line 1718, in handle_user_exception
    reraise(exc_type, exc_value, tb)
  File "/home/lu2905363/PycharmProjects/flask/venv/lib/python3.6/site-packages/flask/_compat.py", line 35, in reraise
    raise value
  File "/home/lu2905363/PycharmProjects/flask/venv/lib/python3.6/site-packages/flask/app.py", line 1813, in full_dispatch_request
    rv = self.dispatch_request()
  File "/home/lu2905363/PycharmProjects/flask/venv/lib/python3.6/site-packages/flask/app.py", line 1799, in dispatch_request
    return self.view_functions[rule.endpoint](**req.view_args)
  File "/home/lu2905363/PycharmProjects/flask/app/routes.py", line 149, in reset_password_request
    if current_user.is_authenticated():
TypeError: 'bool' object is not callable
2018-08-25 17:58:50,979 INFO: Microblog startup [in /home/lu2905363/PycharmProjects/flask/app/__init__.py:48]
2018-08-25 17:58:53,945 ERROR: Exception on /reset_password_request [GET] [in /home/lu2905363/PycharmProjects/flask/venv/lib/python3.6/site-packages/flask/app.py:1761]
Traceback (most recent call last):
  File "/home/lu2905363/PycharmProjects/flask/venv/lib/python3.6/site-packages/flask/app.py", line 2292, in wsgi_app
    response = self.full_dispatch_request()
  File "/home/lu2905363/PycharmProjects/flask/venv/lib/python3.6/site-packages/flask/app.py", line 1815, in full_dispatch_request
    rv = self.handle_user_exception(e)
  File "/home/lu2905363/PycharmProjects/flask/venv/lib/python3.6/site-packages/flask/app.py", line 1718, in handle_user_exception
    reraise(exc_type, exc_value, tb)
  File "/home/lu2905363/PycharmProjects/flask/venv/lib/python3.6/site-packages/flask/_compat.py", line 35, in reraise
    raise value
  File "/home/lu2905363/PycharmProjects/flask/venv/lib/python3.6/site-packages/flask/app.py", line 1813, in full_dispatch_request
    rv = self.dispatch_request()
  File "/home/lu2905363/PycharmProjects/flask/venv/lib/python3.6/site-packages/flask/app.py", line 1799, in dispatch_request
    return self.view_functions[rule.endpoint](**req.view_args)
  File "/home/lu2905363/PycharmProjects/flask/app/routes.py", line 149, in reset_password_request
    if current_user.is_authenticated():
TypeError: 'bool' object is not callable
2018-08-25 18:01:08,617 INFO: Microblog startup [in /home/lu2905363/PycharmProjects/flask/app/__init__.py:48]
2018-08-25 18:02:35,740 INFO: Microblog startup [in /home/lu2905363/PycharmProjects/flask/app/__init__.py:48]
2018-08-25 18:02:47,741 ERROR: Exception on /reset_password_request [POST] [in /home/lu2905363/PycharmProjects/flask/venv/lib/python3.6/site-packages/flask/app.py:1761]
Traceback (most recent call last):
  File "/home/lu2905363/PycharmProjects/flask/venv/lib/python3.6/site-packages/flask/app.py", line 2292, in wsgi_app
    response = self.full_dispatch_request()
  File "/home/lu2905363/PycharmProjects/flask/venv/lib/python3.6/site-packages/flask/app.py", line 1815, in full_dispatch_request
    rv = self.handle_user_exception(e)
  File "/home/lu2905363/PycharmProjects/flask/venv/lib/python3.6/site-packages/flask/app.py", line 1718, in handle_user_exception
    reraise(exc_type, exc_value, tb)
  File "/home/lu2905363/PycharmProjects/flask/venv/lib/python3.6/site-packages/flask/_compat.py", line 35, in reraise
    raise value
  File "/home/lu2905363/PycharmProjects/flask/venv/lib/python3.6/site-packages/flask/app.py", line 1813, in full_dispatch_request
    rv = self.dispatch_request()
  File "/home/lu2905363/PycharmProjects/flask/venv/lib/python3.6/site-packages/flask/app.py", line 1799, in dispatch_request
    return self.view_functions[rule.endpoint](**req.view_args)
  File "/home/lu2905363/PycharmProjects/flask/app/routes.py", line 155, in reset_password_request
    send_password_reset_email(user)
  File "/home/lu2905363/PycharmProjects/flask/app/email.py", line 14, in send_password_reset_email
    token = user.get_reset_password_token()
  File "/home/lu2905363/PycharmProjects/flask/app/models.py", line 42, in get_reset_password_token
    algorithm='HS256'.decode('utf-8'))
AttributeError: 'str' object has no attribute 'decode'
2018-08-25 18:04:49,802 INFO: Microblog startup [in /home/lu2905363/PycharmProjects/flask/app/__init__.py:48]
